Workbook

Sheet Servicios
A1: Fecha | B1: Cliente | C1: Ciudad | D1: Ubicación | E1: Servicio | F1: Cantidad | G1: Precio unitario | H1: Total | I1: Medio de pago | J1: Pagado | K1: Notas | L1: Mes | M1: Año | N1: Semana | O1: Columna 1
A2: 45887 | B2: Catalina | C2: Nancagua | D2: nancagua | E2: Lavado Alfombra | F2: 1 | G2: 16000 | H2: =IFERROR(F2*G2,"") -> 16000 | I2: Efectivo | J2: si | K2: Conocido | L2: =IFERROR(MONTH(A2),"") -> 8 | M2: =IFERROR(YEAR(A2),"") -> 2025 | N2: =IFERROR(WEEKNUM(A2,2),"") -> 34 | O2: =TEXT(L2,"0")&"-"&M2 -> 8-2025 | Q2: Web
A3: 45910 | B3: Eva Gonzalez | C3: Santa Cruz | D3: santa cruz | E3: Lavado alfombra muro a muro y escaleras | F3: 1 | G3: 82240 | H3: =IFERROR(F3*G3,"") -> 82240 | I3: Transferencia | J3: si | L3: =IFERROR(MONTH(A3),"") -> 9 | M3: =IFERROR(YEAR(A3),"") -> 2025 | N3: =IFERROR(WEEKNUM(A3,2),"") -> 37 | O3: =TEXT(L3,"0")&"-"&M3 -> 9-2025 | Q3: Instagram
A4: 45903 | B4: Vale garcía | C4: Chimbarongo | D4: Chimbarongo | E4: Sillon y 3 sillas | F4: 1 | G4: 35000 | H4: =IFERROR(F4*G4,"") -> 35000 | I4: Efectivo | J4: si | K4: Instagram | L4: =IFERROR(MONTH(A4),"") -> 9 | M4: =IFERROR(YEAR(A4),"") -> 2025 | N4: =IFERROR(WEEKNUM(A4,2),"") -> 36 | O4: =TEXT(L4,"0")&"-"&M4 -> 9-2025 | Q4: Referidos
A5: 45903 | B5: Amparo Ortiz | C5: Santa Cruz | D5: santa cruz | E5: Tapiz auto hachtback | F5: 1 | G5: 23000 | H5: =IFERROR(F5*G5,"") -> 23000 | I5: Transferencia | J5: si | K5: Instagram | L5: =IFERROR(MONTH(A5),"") -> 9 | M5: =IFERROR(YEAR(A5),"") -> 2025 | N5: =IFERROR(WEEKNUM(A5,2),"") -> 36 | O5: =TEXT(L5,"0")&"-"&M5 -> 9-2025 | Q5: Cocnocido
A6: 45906 | B6: Maria paredes | C6: San Fernando | D6: San Fernando | E6: Sillones y sillas | F6: 1 | G6: 50000 | H6: =IFERROR(F6*G6,"") -> 50000 | I6: Transferencia | J6: si | K6: Instagram | L6: =IFERROR(MONTH(A6),"") -> 9 | M6: =IFERROR(YEAR(A6),"") -> 2025 | N6: =IFERROR(WEEKNUM(A6,2),"") -> 36 | O6: =TEXT(L6,"0")&"-"&M6 -> 9-2025
A7: 45901 | B7: Danilo Gonzalez | C7: Santa Cruz | D7: santa cruz | E7: Sillon | F7: 1 | G7: 15000 | H7: =IFERROR(F7*G7,"") -> 15000 | I7: Transferencia | J7: si | K7: Instagram | L7: =IFERROR(MONTH(A7),"") -> 9 | M7: =IFERROR(YEAR(A7),"") -> 2025 | N7: =IFERROR(WEEKNUM(A7,2),"") -> 36 | O7: =TEXT(L7,"0")&"-"&M7 -> 9-2025
A8: 45893 | B8: Daniela Vergara | C8: Santa Cruz | D8: santa cruz | E8: Sillón y 2 alfombras | F8: 1 | G8: 49000 | H8: =IFERROR(F8*G8,"") -> 49000 | I8: Transferencia | J8: si | K8: Instagram | L8: =IFERROR(MONTH(A8),"") -> 8 | M8: =IFERROR(YEAR(A8),"") -> 2025 | N8: =IFERROR(WEEKNUM(A8,2),"") -> 34 | O8: =TEXT(L8,"0")&"-"&M8 -> 8-2025
A9: 45911 | B9: Lore hernandez | C9: Santa Cruz | D9: santa cruz | E9: 2 sillones 1 alfombra | F9: 1 | G9: 45200 | H9: =IFERROR(F9*G9,"") -> 45200 | I9: Efectivo | J9: si | K9: Instagram | L9: =IFERROR(MONTH(A9),"") -> 9 | M9: =IFERROR(YEAR(A9),"") -> 2025 | N9: =IFERROR(WEEKNUM(A9,2),"") -> 37 | O9: =TEXT(L9,"0")&"-"&M9 -> 9-2025
A10: 45913 | B10: Camila Oyarce | C10: San Fernando | D10: San Fernando | E10: 1 colchón 2 plazas | F10: 1 | G10: 25000 | H10: =IFERROR(F10*G10,"") -> 25000 | I10: Efectivo | J10: si | K10: Instagram | L10: =IFERROR(MONTH(A10),"") -> 9 | M10: =IFERROR(YEAR(A10),"") -> 2025 | N10: =IFERROR(WEEKNUM(A10,2),"") -> 37 | O10: =TEXT(L10,"0")&"-"&M10 -> 9-2025
A11: 45915 | B11: Gisel | C11: San Fernando | D11: San Fernando | E11: 1 colchón 2 plazas | F11: 1 | G11: 25000 | H11: =IFERROR(F11*G11,"") -> 25000 | I11: Efectivo | J11: si | K11: Instagram | L11: =IFERROR(MONTH(A11),"") -> 9 | M11: =IFERROR(YEAR(A11),"") -> 2025 | N11: =IFERROR(WEEKNUM(A11,2),"") -> 38 | O11: =TEXT(L11,"0")&"-"&M11 -> 9-2025
A12: 45915 | B12: Claudia Canizares | C12: Santa Cruz | D12: santa cruz | E12: Escalera y pasillo | F12: 1 | G12: 28600 | H12: =IFERROR(F12*G12,"") -> 28600 | I12: Transferencia | J12: si | K12: Instagram | L12: =IFERROR(MONTH(A12),"") -> 9 | M12: =IFERROR(YEAR(A12),"") -> 2025 | N12: =IFERROR(WEEKNUM(A12,2),"") -> 38 | O12: =TEXT(L12,"0")&"-"&M12 -> 9-2025
A13: 45925 | B13: Carlos Rivera | C13: San Fernando | D13: San Fernando | E13: Sillon 4 cuerpos L | F13: 1 | G13: 45000 | H13: =IFERROR(F13*G13,"") -> 45000 | I13: Transferencia | J13: si | K13: Instagram | L13: =IFERROR(MONTH(A13),"") -> 9 | M13: =IFERROR(YEAR(A13),"") -> 2025 | N13: =IFERROR(WEEKNUM(A13,2),"") -> 39 | O13: =TEXT(L13,"0")&"-"&M13 -> 9-2025
A14: 45929 | B14: Adriana Castillo | C14: Santa Cruz | D14: Santa cruz | E14: colchon 1 plaza | F14: 1 | G14: 20000 | H14: =IFERROR(F14*G14,"") -> 20000 | I14: Efectivo | J14: si | K14: Instagram | L14: =IFERROR(MONTH(A14),"") -> 9 | M14: =IFERROR(YEAR(A14),"") -> 2025 | N14: =IFERROR(WEEKNUM(A14,2),"") -> 40 | O14: =TEXT(L14,"0")&"-"&M14 -> 9-2025
A15: 45930 | B15: Ange Farias | C15: Santa Cruz | D15: Santa cruz | E15: Sillón 2 cuerpos | F15: 1 | G15: 31500 | H15: =IFERROR(F15*G15,"") -> 31500 | I15: Transferencia | J15: si | K15: Instagram | L15: =IFERROR(MONTH(A15),"") -> 9 | M15: =IFERROR(YEAR(A15),"") -> 2025 | N15: =IFERROR(WEEKNUM(A15,2),"") -> 40 | O15: =TEXT(L15,"0")&"-"&M15 -> 9-2025
A16: 45931 | B16: Daniel Lobos | C16: Chimbarongo | D16: Chimbarongo | E16: colchon king | F16: 1 | G16: 30000 | H16: =IFERROR(F16*G16,"") -> 30000 | I16: Transferencia | J16: si | K16: Instagram | L16: =IFERROR(MONTH(A16),"") -> 10 | M16: =IFERROR(YEAR(A16),"") -> 2025 | N16: =IFERROR(WEEKNUM(A16,2),"") -> 40 | O16: =TEXT(L16,"0")&"-"&M16 -> 10-2025
A17: 45932 | B17: Angela Urrea | C17: Chimbarongo | D17: Tinguiririca | E17: Colchon 2 plazas 1 cara | F17: 1 | G17: 20000 | H17: =IFERROR(F17*G17,"") -> 20000 | I17: Transferencia | J17: si | K17: Instagram | L17: =IFERROR(MONTH(A17),"") -> 10 | M17: =IFERROR(YEAR(A17),"") -> 2025 | N17: =IFERROR(WEEKNUM(A17,2),"") -> 40 | O17: =TEXT(L17,"0")&"-"&M17 -> 10-2025
... A20: 45936 | B20: Catherine Muñoz | C20: Chimbarongo | D20: Carrizal | E20: Auto hachtback | F20: 1 | G20: 35000 | H20: =IFERROR(F20*G20,"") -> 35000 | I20: Transferencia | J20: si | K20: Instagram | L20: =IFERROR(MONTH(A20),"") -> 10 | M20: =IFERROR(YEAR(A20),"") -> 2025 | N20: =IFERROR(WEEKNUM(A20,2),"") -> 41 | O20: =TEXT(L20,"0")&"-"&M20 -> 10-2025
A21: 45936 | B21: Gissele Rivas | C21: San Fernando | D21: San Fernando | E21: Colchon 2 plazas 2 caras | F21: 1 | G21: 25000 | H21: =IFERROR(F21*G21,"") -> 25000 | I21: Transferencia | J21: si | L21: =IFERROR(MONTH(A21),"") -> 10 | M21: =IFERROR(YEAR(A21),"") -> 2025 | N21: =IFERROR(WEEKNUM(A21,2),"") -> 41 | O21: =TEXT(L21,"0")&"-"&M21 -> 10-2025
A22: 45937 | B22: Claudia Pavez | C22: San Fernando | D22: San Fernando | E22: 1 sillón 3 cuerpos 2 un cuerpo | F22: 1 | G22: 55800 | H22: =IFERROR(F22*G22,"") -> 55800 | I22: Transferencia | J22: si | L22: =IFERROR(MONTH(A22),"") -> 10 | M22: =IFERROR(YEAR(A22),"") -> 2025 | N22: =IFERROR(WEEKNUM(A22,2),"") -> 41 | O22: =TEXT(L22,"0")&"-"&M22 -> 10-2025
A23: 45938 | B23: Julia Acevedo | C23: Santa Cruz | D23: EL guindo | E23: 1 colchon 2 plazas, 1 colchon 1.5, sill+on 2 cuerpos y sillón 1 cuerpo | F23: 1 | G23: 110000 | H23: =IFERROR(F23*G23,"") -> 110000 | I23: Transferencia | J23: si | L23: =IFERROR(MONTH(A23),"") -> 10 | M23: =IFERROR(YEAR(A23),"") -> 2025 | N23: =IFERROR(WEEKNUM(A23,2),"") -> 41 | O23: =TEXT(L23,"0")&"-"&M23 -> 10-2025
A24: 45940 | B24: Mony García | C24: San Fernando | D24: San Fernando | E24: Sillón 4 cuerpos seccional | F24: 1 | G24: 45000 | H24: =IFERROR(F24*G24,"") -> 45000 | I24: Transferencia | J24: si | L24: =IFERROR(MONTH(A24),"") -> 10 | M24: =IFERROR(YEAR(A24),"") -> 2025 | N24: =IFERROR(WEEKNUM(A24,2),"") -> 41 | O24: =TEXT(L24,"0")&"-"&M24 -> 10-2025
A25: 45941 | B25: Maria Ernestina Paredes | C25: Santa Cruz | D25: EL Guindo Alto | E25: Sillón 2 cuerpos, sillón 3 cuerpos | F25: 1 | G25: 76000 | H25: =IFERROR(F25*G25,"") -> 76000 | I25: Transferencia | J25: Si | L25: =IFERROR(MONTH(A25),"") -> 10 | M25: =IFERROR(YEAR(A25),"") -> 2025 | N25: =IFERROR(WEEKNUM(A25,2),"") -> 41 | O25: =TEXT(L25,"0")&"-"&M25 -> 10-2025
A26: 45943 | B26: AlexBarberClub | C26: San Fernando | D26: San Fernando | E26: Sillón 1 cuerpo | F26: 1 | G26: 30000 | H26: =IFERROR(F26*G26,"") -> 30000 | I26: Transferencia | J26: si | L26: =IFERROR(MONTH(A26),"") -> 10 | M26: =IFERROR(YEAR(A26),"") -> 2025 | N26: =IFERROR(WEEKNUM(A26,2),"") -> 42 | O26: =TEXT(L26,"0")&"-"&M26 -> 10-2025
A27: 45944 | B27: Mabe | C27: Santa Cruz | D27: Santa Cruz | E27: Sillón 3 cuerpos, 2 sillón 1 cuerpo, 5 sillas | F27: 1 | G27: 70000 | H27: =IFERROR(F27*G27,"") -> 70000 | I27: Efectivo | J27: si | L27: =IFERROR(MONTH(A27),"") -> 10 | M27: =IFERROR(YEAR(A27),"") -> 2025 | N27: =IFERROR(WEEKNUM(A27,2),"") -> 42 | O27: =TEXT(L27,"0")&"-"&M27 -> 10-2025
A28: 45945 | B28: Carlita Moreira | C28: San Fernando | D28: San fernando | E28: Sillón 3 cuerpos x 2, escaleta 10 peldaños | F28: 1 | G28: 95100 | H28: =IFERROR(F28*G28,"") -> 95100 | I28: Transferencia | J28: si | L28: =IFERROR(MONTH(A28),"") -> 10 | M28: =IFERROR(YEAR(A28),"") -> 2025 | N28: =IFERROR(WEEKNUM(A28,2),"") -> 42 | O28: =TEXT(L28,"0")&"-"&M28 -> 10-2025
A29: 45945 | B29: Isidora Ruiz de Gamboa | C29: Santa Cruz | D29: Santa Cruz | E29: Sillón 3 cuerpos, sillón 2 cuerpos | F29: 1 | G29: 50000 | H29: =IFERROR(F29*G29,"") -> 50000 | I29: Transferencia | J29: Si | L29: =IFERROR(MONTH(A29),"") -> 10 | M29: =IFERROR(YEAR(A29),"") -> 2025 | N29: =IFERROR(WEEKNUM(A29,2),"") -> 42 | O29: =TEXT(L29,"0")&"-"&M29 -> 10-2025
A30: 45947 | B30: Veronica sepulveda | C30: San Fernando | D30: San fernando | E30: Colchon 2 plazas | F30: 1 | G30: 30000 | H30: =IFERROR(F30*G30,"") -> 30000 | I30: Transferencia | J30: si | L30: =IFERROR(MONTH(A30),"") -> 10 | M30: =IFERROR(YEAR(A30),"") -> 2025 | N30: =IFERROR(WEEKNUM(A30,2),"") -> 42 | O30: =TEXT(L30,"0")&"-"&M30 -> 10-2025
A31: 45947 | B31: Ursula gallardo | C31: San Fernando | D31: San fernando | E31: Respaldo cama 2 plazas | F31: 1 | G31: 18000 | H31: =IFERROR(F31*G31,"") -> 18000 | I31: Transferencia | J31: si | L31: =IFERROR(MONTH(A31),"") -> 10 | M31: =IFERROR(YEAR(A31),"") -> 2025 | N31: =IFERROR(WEEKNUM(A31,2),"") -> 42 | O31: =TEXT(L31,"0")&"-"&M31 -> 10-2025
A32: 45948 | B32: Erick zahlhaas | C32: Santa Cruz | D32: Santa Cruz | E32: Sillón seccional 4 cuerpos | F32: 1 | G32: 45000 | H32: =IFERROR(F32*G32,"") -> 45000 | I32: Transferencia | J32: Si | L32: =IFERROR(MONTH(A32),"") -> 10 | M32: =IFERROR(YEAR(A32),"") -> 2025 | N32: =IFERROR(WEEKNUM(A32,2),"") -> 42 | O32: =TEXT(L32,"0")&"-"&M32 -> 10-2025
... A51: 45968 | B51: Camila Lorca | C51: Santa Cruz | D51: El guindo | E51: Colchón king | F51: 1 | G51: 35000 | H51: =IFERROR(F51*G51,"") -> 35000 | I51: Transferencia | J51: si | L51: =IFERROR(MONTH(A51),"") -> 11 | M51: =IFERROR(YEAR(A51),"") -> 2025 | N51: =IFERROR(WEEKNUM(A51,2),"") -> 45 | O51: =TEXT(L51,"0")&"-"&M51 -> 11-2025
A52: 45969 | B52: Jona | C52: San Fernando | D52: San Fernando | E52: Suv 3 corridas | F52: 1 | G52: 50000 | H52: =IFERROR(F52*G52,"") -> 50000 | I52: Transferencia | J52: si | K52: Web | L52: =IFERROR(MONTH(A52),"") -> 11 | M52: =IFERROR(YEAR(A52),"") -> 2025 | N52: =IFERROR(WEEKNUM(A52,2),"") -> 45 | O52: =TEXT(L52,"0")&"-"&M52 -> 11-2025
A53: 45972 | B53: Nati Quiroga | C53: San Fernando | D53: La Paloma | E53: SIllón y sillas | F53: 1 | G53: 59500 | H53: =IFERROR(F53*G53,"") -> 59500 | I53: Transferencia | J53: si | L53: =IFERROR(MONTH(A53),"") -> 11 | M53: =IFERROR(YEAR(A53),"") -> 2025 | N53: =IFERROR(WEEKNUM(A53,2),"") -> 46 | O53: =TEXT(L53,"0")&"-"&M53 -> 11-2025
A54: 45973 | B54: Antonella Quintanilla | C54: Chimbarongo | D54: La cuesta | E54: 2 sillón 2 cuerpos | F54: 1 | G54: 60000 | H54: =IFERROR(F54*G54,"") -> 60000 | I54: Transferencia | J54: si | L54: =IFERROR(MONTH(A54),"") -> 11 | M54: =IFERROR(YEAR(A54),"") -> 2025 | N54: =IFERROR(WEEKNUM(A54,2),"") -> 46 | O54: =TEXT(L54,"0")&"-"&M54 -> 11-2025
A55: 45974 | B55: Mauricio Cornejo Celsi | C55: San Fernando | D55: San fernando | E55: Sillón + jeep | F55: 1 | G55: 72000 | H55: =IFERROR(F55*G55,"") -> 72000 | I55: Transferencia | J55: si | L55: =IFERROR(MONTH(A55),"") -> 11 | M55: =IFERROR(YEAR(A55),"") -> 2025 | N55: =IFERROR(WEEKNUM(A55,2),"") -> 46 | O55: =TEXT(L55,"0")&"-"&M55 -> 11-2025
A56: 45974 | B56: Juan José Aranda Mela | C56: Chimbarongo | D56: Chimbarongo | E56: Sillón 2 cuerpos | F56: 1 | G56: 30000 | H56: =IFERROR(F56*G56,"") -> 30000 | I56: Transferencia | J56: si | L56: =IFERROR(MONTH(A56),"") -> 11 | M56: =IFERROR(YEAR(A56),"") -> 2025 | N56: =IFERROR(WEEKNUM(A56,2),"") -> 46 | O56: =TEXT(L56,"0")&"-"&M56 -> 11-2025
A57: 45975 | B57: Nicol fernandez | C57: San Fernando | D57: San fernando | E57: Sillón 2 cuerpos - sillón 3 cuerpos | F57: 1 | G57: 58500 | H57: =IFERROR(F57*G57,"") -> 58500 | I57: Efectivo | J57: si | L57: =IFERROR(MONTH(A57),"") -> 11 | M57: =IFERROR(YEAR(A57),"") -> 2025 | N57: =IFERROR(WEEKNUM(A57,2),"") -> 46 | O57: =TEXT(L57,"0")&"-"&M57 -> 11-2025
A58: 45978 | B58: kathy Lizana | C58: San Fernando | D58: Talcarehue | E58: sillón 4 cuerpos - 6 sillas | F58: 1 | G58: 76000 | H58: =IFERROR(F58*G58,"") -> 76000 | I58: Transferencia | J58: si | L58: =IFERROR(MONTH(A58),"") -> 11 | M58: =IFERROR(YEAR(A58),"") -> 2025 | N58: =IFERROR(WEEKNUM(A58,2),"") -> 47 | O58: =TEXT(L58,"0")&"-"&M58 -> 11-2025
A59: 45979 | B59: Darneiry Graterol | C59: Santa Cruz | D59: Santa Cruz | E59: Sillón 4 cuerpos | F59: 1 | G59: 45000 | H59: =IFERROR(F59*G59,"") -> 45000 | I59: Transferencia | J59: si | L59: =IFERROR(MONTH(A59),"") -> 11 | M59: =IFERROR(YEAR(A59),"") -> 2025 | N59: =IFERROR(WEEKNUM(A59,2),"") -> 47 | O59: =TEXT(L59,"0")&"-"&M59 -> 11-2025
A60: 45979 | B60: Tamara Apablaza | C60: San Fernando | D60: San fernando | E60: colchon king | F60: 1 | G60: 35000 | H60: =IFERROR(F60*G60,"") -> 35000 | I60: Transferencia | J60: si | L60: =IFERROR(MONTH(A60),"") -> 11 | M60: =IFERROR(YEAR(A60),"") -> 2025 | N60: =IFERROR(WEEKNUM(A60,2),"") -> 47 | O60: =TEXT(L60,"0")&"-"&M60 -> 11-2025
...

Sheet Gastos
A1: Fecha | B1: Categoría | C1: Descripción | D1: Monto | E1: Medio de pago | F1: Mes | G1: Año | H1: Semana
A2: 45887 | B2: Arriendo | C2: Abrillatadora | D2: 27000 | E2: tarjeta
A3: 45893 | B3: Arriendo | C3: Abrillatadora | D3: 8500 | E3: tarjeta
A4: 45906 | B4: pago | C4: pago Joan | D4: 20000 | E4: Efectivo | F4: =IFERROR(MONTH(A4),"") -> 9 | G4: =IFERROR(YEAR(A4),"") -> 2025 | H4: =IFERROR(WEEKNUM(A4,2),"") -> 36
A5: 45906 | B5: Combustible | C5: Bencina | D5: 20000 | E5: Efectivo | F5: =IFERROR(MONTH(A5),"") -> 9 | G5: =IFERROR(YEAR(A5),"") -> 2025 | H5: =IFERROR(WEEKNUM(A5,2),"") -> 36
A6: 45915 | B6: Combustible | C6: Bencina | D6: 20000 | E6: Efectivo | F6: =IFERROR(MONTH(A6),"") -> 9 | G6: =IFERROR(YEAR(A6),"") -> 2025 | H6: =IFERROR(WEEKNUM(A6,2),"") -> 38
A7: 45917 | B7: Publicidad | C7: Facebook | D7: 18900 | E7: mercado pago
A8: 45928 | B8: Publicidad | C8: Facebook | D8: 20000 | E8: mecado pago
A9: 45933 | B9: Combustible | C9: Bencina | D9: 20000 | E9: Efectivo | F9: =IFERROR(MONTH(A9),"") -> 10 | G9: =IFERROR(YEAR(A9),"") -> 2025 | H9: =IFERROR(WEEKNUM(A9,2),"") -> 40
A10: 45948 | B10: Publicidad | C10: Instagram | D10: 25000 | E10: mercado pago | F10: =IFERROR(MONTH(A10),"") -> 10 | G10: =IFERROR(YEAR(A10),"") -> 2025 | H10: =IFERROR(WEEKNUM(A10,2),"") -> 42
A11: 45947 | B11: insumos | C11: alianzaAdn | D11: 38794 | E11: cuenta corriente | F11: =IFERROR(MONTH(A11),"") -> 10 | G11: =IFERROR(YEAR(A11),"") -> 2025 | H11: =IFERROR(WEEKNUM(A11,2),"") -> 42
A12: 45945 | B12: Combustible | C12: Bencina | D12: 20000 | E12: Efectivo | F12: =IFERROR(MONTH(#REF!),"") | G12: =IFERROR(YEAR(#REF!),"") | H12: =IFERROR(WEEKNUM(#REF!,2),"")
A13: 45946 | B13: Materiales | C13: Tubos grises | D13: 22000 | F13: =IFERROR(MONTH(A13),"") -> 10 | G13: =IFERROR(YEAR(A13),"") -> 2025 | H13: =IFERROR(WEEKNUM(A13,2),"") -> 42
A14: 45948 | B14: Activos | C14: Limpiadora a vapor karcher | D14: 237980 | E14: Mercado pago | F14: =IFERROR(MONTH(A14),"") -> 10 | G14: =IFERROR(YEAR(A14),"") -> 2025 | H14: =IFERROR(WEEKNUM(A14,2),"") -> 42
A15: 45760 | B15: insumos | C15: Percarbonato | D15: 17830 | E15: Mercado pago | F15: =IFERROR(MONTH(A15),"") -> 4 | G15: =IFERROR(YEAR(A15),"") -> 2025 | H15: =IFERROR(WEEKNUM(A15,2),"") -> 15
F16: =IFERROR(MONTH(A16),"") -> 12 | G16: =IFERROR(YEAR(A16),"") -> 1899 | H16: =IFERROR(WEEKNUM(A16,2),"") -> 53
F17: =IFERROR(MONTH(A17),"") -> 12 | G17: =IFERROR(YEAR(A17),"") -> 1899 | H17: =IFERROR(WEEKNUM(A17,2),"") -> 53
F18: =IFERROR(MONTH(A18),"") -> 12 | G18: =IFERROR(YEAR(A18),"") -> 1899 | H18: =IFERROR(WEEKNUM(A18,2),"") -> 53
F19: =IFERROR(MONTH(A19),"") -> 12 | G19: =IFERROR(YEAR(A19),"") -> 1899 | H19: =IFERROR(WEEKNUM(A19,2),"") -> 53
F20: =IFERROR(MONTH(A20),"") -> 12 | G20: =IFERROR(YEAR(A20),"") -> 1899 | H20: =IFERROR(WEEKNUM(A20,2),"") -> 53
D21: =SUM(D2:D17) -> 516004 | F21: =IFERROR(MONTH(A21),"") -> 12 | G21: =IFERROR(YEAR(A21),"") -> 1899 | H21: =IFERROR(WEEKNUM(A21,2),"") -> 53
F22: =IFERROR(MONTH(A22),"") -> 12 | G22: =IFERROR(YEAR(A22),"") -> 1899 | H22: =IFERROR(WEEKNUM(A22,2),"") -> 53
F23: =IFERROR(MONTH(A23),"") -> 12 | G23: =IFERROR(YEAR(A23),"") -> 1899 | H23: =IFERROR(WEEKNUM(A23,2),"") -> 53
F24: =IFERROR(MONTH(A24),"") -> 12 | G24: =IFERROR(YEAR(A24),"") -> 1899 | H24: =IFERROR(WEEKNUM(A24,2),"") -> 53
F25: =IFERROR(MONTH(A25),"") -> 12 | G25: =IFERROR(YEAR(A25),"") -> 1899 | H25: =IFERROR(WEEKNUM(A25,2),"") -> 53
F26: =IFERROR(MONTH(A26),"") -> 12 | G26: =IFERROR(YEAR(A26),"") -> 1899 | H26: =IFERROR(WEEKNUM(A26,2),"") -> 53
F27: =IFERROR(MONTH(A27),"") -> 12 | G27: =IFERROR(YEAR(A27),"") -> 1899 | H27: =IFERROR(WEEKNUM(A27,2),"") -> 53
F28: =IFERROR(MONTH(A28),"") -> 12 | G28: =IFERROR(YEAR(A28),"") -> 1899 | H28: =IFERROR(WEEKNUM(A28,2),"") -> 53
F29: =IFERROR(MONTH(A29),"") -> 12 | G29: =IFERROR(YEAR(A29),"") -> 1899 | H29: =IFERROR(WEEKNUM(A29,2),"") -> 53
F30: =IFERROR(MONTH(A30),"") -> 12 | G30: =IFERROR(YEAR(A30),"") -> 1899 | H30: =IFERROR(WEEKNUM(A30,2),"") -> 53
F31: =IFERROR(MONTH(A31),"") -> 12 | G31: =IFERROR(YEAR(A31),"") -> 1899 | H31: =IFERROR(WEEKNUM(A31,2),"") -> 53
F32: =IFERROR(MONTH(A32),"") -> 12 | G32: =IFERROR(YEAR(A32),"") -> 1899 | H32: =IFERROR(WEEKNUM(A32,2),"") -> 53
F33: =IFERROR(MONTH(A33),"") -> 12 | G33: =IFERROR(YEAR(A33),"") -> 1899 | H33: =IFERROR(WEEKNUM(A33,2),"") -> 53
... F55: =IFERROR(MONTH(A55),"") -> 12 | G55: =IFERROR(YEAR(A55),"") -> 1899 | H55: =IFERROR(WEEKNUM(A55,2),"") -> 53

Sheet Semanal
A1: Parámetros | B1: Ingresos por servicios | C1: Otros ingresos | D1: Total ingresos | E1: Costos variables (insumos) | F1: Combustible | G1: Sueldos | H1: Otros gastos fijos | I1: Total egresos | J1: Flujo neto | K1: Saldo acumulado
A2: Mes (número) | B2: 9
A3: Año | B3: 2025
A4: Semana 3
A5: Resumen Semanal (según Mes/Año arriba)
A6: Semana 5
A7: Semana 1 | B7: =SUMIFS(Servicios!G:G,Servicios!L:L,$B$3,Servicios!K:K,$B$2,Servicios!M:M,1) -> 0 | D7: =B7+C7 -> 0 | E7: =SUMIFS(Gastos!D:D,Gastos!G:G,$B$3,Gastos!F:F,$B$2,Gastos!H:H,1,Gastos!B:B,"Insumos") -> 0 | F7: =SUMIFS(Gastos!D:D,Gastos!G:G,$B$3,Gastos!F:F,$B$2,Gastos!H:H,1,Gastos!B:B,"Combustible") -> 0 | G7: =SUMIFS(Gastos!D:D,Gastos!G:G,$B$3,Gastos!F:F,$B$2,Gastos!H:H,1,Gastos!B:B,"Sueldos") -> 0 | H7: =SUMIFS(Gastos!D:D,Gastos!G:G,$B$3,Gastos!F:F,$B$2,Gastos!H:H,1,Gastos!B:B,"Otros") -> 0 | I7: =E7+F7+G7+H7 -> 0 | J7: =D7-I7 -> 0 | K7: =J7 -> 0
A8: Semana 2 | B8: =SUMIFS(Servicios!G:G,Servicios!L:L,$B$3,Servicios!K:K,$B$2,Servicios!M:M,2) -> 0 | D8: =B8+C8 -> 0 | E8: =SUMIFS(Gastos!D:D,Gastos!G:G,$B$3,Gastos!F:F,$B$2,Gastos!H:H,2,Gastos!B:B,"Insumos") -> 0 | F8: =SUMIFS(Gastos!D:D,Gastos!G:G,$B$3,Gastos!F:F,$B$2,Gastos!H:H,2,Gastos!B:B,"Combustible") -> 0 | G8: =SUMIFS(Gastos!D:D,Gastos!G:G,$B$3,Gastos!F:F,$B$2,Gastos!H:H,2,Gastos!B:B,"Sueldos") -> 0 | H8: =SUMIFS(Gastos!D:D,Gastos!G:G,$B$3,Gastos!F:F,$B$2,Gastos!H:H,2,Gastos!B:B,"Otros") -> 0 | I8: =E8+F8+G8+H8 -> 0 | J8: =D8-I8 -> 0 | K8: =K7+J8 -> 0
A9: Semana 3 | B9: =SUMIFS(Servicios!G:G,Servicios!L:L,$B$3,Servicios!K:K,$B$2,Servicios!M:M,3) -> 0 | D9: =B9+C9 -> 0 | E9: =SUMIFS(Gastos!D:D,Gastos!G:G,$B$3,Gastos!F:F,$B$2,Gastos!H:H,3,Gastos!B:B,"Insumos") -> 0 | F9: =SUMIFS(Gastos!D:D,Gastos!G:G,$B$3,Gastos!F:F,$B$2,Gastos!H:H,3,Gastos!B:B,"Combustible") -> 0 | G9: =SUMIFS(Gastos!D:D,Gastos!G:G,$B$3,Gastos!F:F,$B$2,Gastos!H:H,3,Gastos!B:B,"Sueldos") -> 0 | H9: =SUMIFS(Gastos!D:D,Gastos!G:G,$B$3,Gastos!F:F,$B$2,Gastos!H:H,3,Gastos!B:B,"Otros") -> 0 | I9: =E9+F9+G9+H9 -> 0 | J9: =D9-I9 -> 0 | K9: =K8+J9 -> 0
A10: Semana 4 | B10: =SUMIFS(Servicios!G:G,Servicios!L:L,$B$3,Servicios!K:K,$B$2,Servicios!M:M,4) -> 0 | D10: =B10+C10 -> 0 | E10: =SUMIFS(Gastos!D:D,Gastos!G:G,$B$3,Gastos!F:F,$B$2,Gastos!H:H,4,Gastos!B:B,"Insumos") -> 0 | F10: =SUMIFS(Gastos!D:D,Gastos!G:G,$B$3,Gastos!F:F,$B$2,Gastos!H:H,4,Gastos!B:B,"Combustible") -> 0 | G10: =SUMIFS(Gastos!D:D,Gastos!G:G,$B$3,Gastos!F:F,$B$2,Gastos!H:H,4,Gastos!B:B,"Sueldos") -> 0 | H10: =SUMIFS(Gastos!D:D,Gastos!G:G,$B$3,Gastos!F:F,$B$2,Gastos!H:H,4,Gastos!B:B,"Otros") -> 0 | I10: =E10+F10+G10+H10 -> 0 | J10: =D10-I10 -> 0 | K10: =K9+J10 -> 0
A11: Semana 5 | B11: =SUMIFS(Servicios!G:G,Servicios!L:L,$B$3,Servicios!K:K,$B$2,Servicios!M:M,5) -> 0 | D11: =B11+C11 -> 0 | E11: =SUMIFS(Gastos!D:D,Gastos!G:G,$B$3,Gastos!F:F,$B$2,Gastos!H:H,5,Gastos!B:B,"Insumos") -> 0 | F11: =SUMIFS(Gastos!D:D,Gastos!G:G,$B$3,Gastos!F:F,$B$2,Gastos!H:H,5,Gastos!B:B,"Combustible") -> 0 | G11: =SUMIFS(Gastos!D:D,Gastos!G:G,$B$3,Gastos!F:F,$B$2,Gastos!H:H,5,Gastos!B:B,"Sueldos") -> 0 | H11: =SUMIFS(Gastos!D:D,Gastos!G:G,$B$3,Gastos!F:F,$B$2,Gastos!H:H,5,Gastos!B:B,"Otros") -> 0 | I11: =E11+F11+G11+H11 -> 0 | J11: =D11-I11 -> 0 | K11: =K10+J11 -> 0
A12: Semana 6 | B12: =SUMIFS(Servicios!G:G,Servicios!L:L,$B$3,Servicios!K:K,$B$2,Servicios!M:M,5) -> 0 | D12: =B12+C12 -> 0 | E12: =SUMIFS(Gastos!D:D,Gastos!G:G,$B$3,Gastos!F:F,$B$2,Gastos!H:H,5,Gastos!B:B,"Insumos") -> 0 | F12: =SUMIFS(Gastos!D:D,Gastos!G:G,$B$3,Gastos!F:F,$B$2,Gastos!H:H,5,Gastos!B:B,"Combustible") -> 0 | G12: =SUMIFS(Gastos!D:D,Gastos!G:G,$B$3,Gastos!F:F,$B$2,Gastos!H:H,5,Gastos!B:B,"Sueldos") -> 0 | H12: =SUMIFS(Gastos!D:D,Gastos!G:G,$B$3,Gastos!F:F,$B$2,Gastos!H:H,5,Gastos!B:B,"Otros") -> 0 | I12: =E12+F12+G12+H12 -> 0 | J12: =D12-I12 -> 0 | K12: =K11+J12 -> 0
A13: Semana 7 | B13: =SUMIFS(Servicios!G:G,Servicios!L:L,$B$3,Servicios!K:K,$B$2,Servicios!M:M,5) -> 0 | D13: =B13+C13 -> 0 | E13: =SUMIFS(Gastos!D:D,Gastos!G:G,$B$3,Gastos!F:F,$B$2,Gastos!H:H,5,Gastos!B:B,"Insumos") -> 0 | F13: =SUMIFS(Gastos!D:D,Gastos!G:G,$B$3,Gastos!F:F,$B$2,Gastos!H:H,5,Gastos!B:B,"Combustible") -> 0 | G13: =SUMIFS(Gastos!D:D,Gastos!G:G,$B$3,Gastos!F:F,$B$2,Gastos!H:H,5,Gastos!B:B,"Sueldos") -> 0 | H13: =SUMIFS(Gastos!D:D,Gastos!G:G,$B$3,Gastos!F:F,$B$2,Gastos!H:H,5,Gastos!B:B,"Otros") -> 0 | I13: =E13+F13+G13+H13 -> 0 | J13: =D13-I13 -> 0 | K13: =K12+J13 -> 0
A14: Semana 8 | B14: =SUMIFS(Servicios!G:G,Servicios!L:L,$B$3,Servicios!K:K,$B$2,Servicios!M:M,5) -> 0 | D14: =B14+C14 -> 0 | E14: =SUMIFS(Gastos!D:D,Gastos!G:G,$B$3,Gastos!F:F,$B$2,Gastos!H:H,5,Gastos!B:B,"Insumos") -> 0 | F14: =SUMIFS(Gastos!D:D,Gastos!G:G,$B$3,Gastos!F:F,$B$2,Gastos!H:H,5,Gastos!B:B,"Combustible") -> 0 | G14: =SUMIFS(Gastos!D:D,Gastos!G:G,$B$3,Gastos!F:F,$B$2,Gastos!H:H,5,Gastos!B:B,"Sueldos") -> 0 | H14: =SUMIFS(Gastos!D:D,Gastos!G:G,$B$3,Gastos!F:F,$B$2,Gastos!H:H,5,Gastos!B:B,"Otros") -> 0 | I14: =E14+F14+G14+H14 -> 0 | J14: =D14-I14 -> 0 | K14: =K13+J14 -> 0
A15: Semana 9 | B15: =SUMIFS(Servicios!G:G,Servicios!L:L,$B$3,Servicios!K:K,$B$2,Servicios!M:M,5) -> 0 | D15: =B15+C15 -> 0 | E15: =SUMIFS(Gastos!D:D,Gastos!G:G,$B$3,Gastos!F:F,$B$2,Gastos!H:H,5,Gastos!B:B,"Insumos") -> 0 | F15: =SUMIFS(Gastos!D:D,Gastos!G:G,$B$3,Gastos!F:F,$B$2,Gastos!H:H,5,Gastos!B:B,"Combustible") -> 0 | G15: =SUMIFS(Gastos!D:D,Gastos!G:G,$B$3,Gastos!F:F,$B$2,Gastos!H:H,5,Gastos!B:B,"Sueldos") -> 0 | H15: =SUMIFS(Gastos!D:D,Gastos!G:G,$B$3,Gastos!F:F,$B$2,Gastos!H:H,5,Gastos!B:B,"Otros") -> 0 | I15: =E15+F15+G15+H15 -> 0 | J15: =D15-I15 -> 0 | K15: =K14+J15 -> 0
A16: Semana 10 | B16: =SUMIFS(Servicios!G:G,Servicios!L:L,$B$3,Servicios!K:K,$B$2,Servicios!M:M,5) -> 0 | D16: =B16+C16 -> 0 | E16: =SUMIFS(Gastos!D:D,Gastos!G:G,$B$3,Gastos!F:F,$B$2,Gastos!H:H,5,Gastos!B:B,"Insumos") -> 0 | F16: =SUMIFS(Gastos!D:D,Gastos!G:G,$B$3,Gastos!F:F,$B$2,Gastos!H:H,5,Gastos!B:B,"Combustible") -> 0 | G16: =SUMIFS(Gastos!D:D,Gastos!G:G,$B$3,Gastos!F:F,$B$2,Gastos!H:H,5,Gastos!B:B,"Sueldos") -> 0 | H16: =SUMIFS(Gastos!D:D,Gastos!G:G,$B$3,Gastos!F:F,$B$2,Gastos!H:H,5,Gastos!B:B,"Otros") -> 0 | I16: =E16+F16+G16+H16 -> 0 | J16: =D16-I16 -> 0 | K16: =K15+J16 -> 0
A17: Semana 11 | B17: =SUMIFS(Servicios!G:G,Servicios!L:L,$B$3,Servicios!K:K,$B$2,Servicios!M:M,5) -> 0 | D17: =B17+C17 -> 0 | E17: =SUMIFS(Gastos!D:D,Gastos!G:G,$B$3,Gastos!F:F,$B$2,Gastos!H:H,5,Gastos!B:B,"Insumos") -> 0 | F17: =SUMIFS(Gastos!D:D,Gastos!G:G,$B$3,Gastos!F:F,$B$2,Gastos!H:H,5,Gastos!B:B,"Combustible") -> 0 | G17: =SUMIFS(Gastos!D:D,Gastos!G:G,$B$3,Gastos!F:F,$B$2,Gastos!H:H,5,Gastos!B:B,"Sueldos") -> 0 | H17: =SUMIFS(Gastos!D:D,Gastos!G:G,$B$3,Gastos!F:F,$B$2,Gastos!H:H,5,Gastos!B:B,"Otros") -> 0 | I17: =E17+F17+G17+H17 -> 0 | J17: =D17-I17 -> 0 | K17: =K16+J17 -> 0
A18: Semana 12 | B18: =SUMIFS(Servicios!G:G,Servicios!L:L,$B$3,Servicios!K:K,$B$2,Servicios!M:M,5) -> 0 | D18: =B18+C18 -> 0 | E18: =SUMIFS(Gastos!D:D,Gastos!G:G,$B$3,Gastos!F:F,$B$2,Gastos!H:H,5,Gastos!B:B,"Insumos") -> 0 | F18: =SUMIFS(Gastos!D:D,Gastos!G:G,$B$3,Gastos!F:F,$B$2,Gastos!H:H,5,Gastos!B:B,"Combustible") -> 0 | G18: =SUMIFS(Gastos!D:D,Gastos!G:G,$B$3,Gastos!F:F,$B$2,Gastos!H:H,5,Gastos!B:B,"Sueldos") -> 0 | H18: =SUMIFS(Gastos!D:D,Gastos!G:G,$B$3,Gastos!F:F,$B$2,Gastos!H:H,5,Gastos!B:B,"Otros") -> 0 | I18: =E18+F18+G18+H18 -> 0 | J18: =D18-I18 -> 0 | K18: =K17+J18 -> 0
A19: Semana 13 | B19: =SUMIFS(Servicios!G:G,Servicios!L:L,$B$3,Servicios!K:K,$B$2,Servicios!M:M,5) -> 0 | D19: =B19+C19 -> 0 | E19: =SUMIFS(Gastos!D:D,Gastos!G:G,$B$3,Gastos!F:F,$B$2,Gastos!H:H,5,Gastos!B:B,"Insumos") -> 0 | F19: =SUMIFS(Gastos!D:D,Gastos!G:G,$B$3,Gastos!F:F,$B$2,Gastos!H:H,5,Gastos!B:B,"Combustible") -> 0 | G19: =SUMIFS(Gastos!D:D,Gastos!G:G,$B$3,Gastos!F:F,$B$2,Gastos!H:H,5,Gastos!B:B,"Sueldos") -> 0 | H19: =SUMIFS(Gastos!D:D,Gastos!G:G,$B$3,Gastos!F:F,$B$2,Gastos!H:H,5,Gastos!B:B,"Otros") -> 0 | I19: =E19+F19+G19+H19 -> 0 | J19: =D19-I19 -> 0 | K19: =K18+J19 -> 0
A20: Semana 14 | B20: =SUMIFS(Servicios!G:G,Servicios!L:L,$B$3,Servicios!K:K,$B$2,Servicios!M:M,5) -> 0 | D20: =B20+C20 -> 0 | E20: =SUMIFS(Gastos!D:D,Gastos!G:G,$B$3,Gastos!F:F,$B$2,Gastos!H:H,5,Gastos!B:B,"Insumos") -> 0 | F20: =SUMIFS(Gastos!D:D,Gastos!G:G,$B$3,Gastos!F:F,$B$2,Gastos!H:H,5,Gastos!B:B,"Combustible") -> 0 | G20: =SUMIFS(Gastos!D:D,Gastos!G:G,$B$3,Gastos!F:F,$B$2,Gastos!H:H,5,Gastos!B:B,"Sueldos") -> 0 | H20: =SUMIFS(Gastos!D:D,Gastos!G:G,$B$3,Gastos!F:F,$B$2,Gastos!H:H,5,Gastos!B:B,"Otros") -> 0 | I20: =E20+F20+G20+H20 -> 0 | J20: =D20-I20 -> 0 | K20: =K19+J20 -> 0
A21: Semana 15 | B21: =SUMIFS(Servicios!G:G,Servicios!L:L,$B$3,Servicios!K:K,$B$2,Servicios!M:M,5) -> 0 | D21: =B21+C21 -> 0 | E21: =SUMIFS(Gastos!D:D,Gastos!G:G,$B$3,Gastos!F:F,$B$2,Gastos!H:H,5,Gastos!B:B,"Insumos") -> 0 | F21: =SUMIFS(Gastos!D:D,Gastos!G:G,$B$3,Gastos!F:F,$B$2,Gastos!H:H,5,Gastos!B:B,"Combustible") -> 0 | G21: =SUMIFS(Gastos!D:D,Gastos!G:G,$B$3,Gastos!F:F,$B$2,Gastos!H:H,5,Gastos!B:B,"Sueldos") -> 0 | H21: =SUMIFS(Gastos!D:D,Gastos!G:G,$B$3,Gastos!F:F,$B$2,Gastos!H:H,5,Gastos!B:B,"Otros") -> 0 | I21: =E21+F21+G21+H21 -> 0 | J21: =D21-I21 -> 0 | K21: =K20+J21 -> 0
A22: Semana 16 | B22: =SUMIFS(Servicios!G:G,Servicios!L:L,$B$3,Servicios!K:K,$B$2,Servicios!M:M,5) -> 0 | D22: =B22+C22 -> 0 | E22: =SUMIFS(Gastos!D:D,Gastos!G:G,$B$3,Gastos!F:F,$B$2,Gastos!H:H,5,Gastos!B:B,"Insumos") -> 0 | F22: =SUMIFS(Gastos!D:D,Gastos!G:G,$B$3,Gastos!F:F,$B$2,Gastos!H:H,5,Gastos!B:B,"Combustible") -> 0 | G22: =SUMIFS(Gastos!D:D,Gastos!G:G,$B$3,Gastos!F:F,$B$2,Gastos!H:H,5,Gastos!B:B,"Sueldos") -> 0 | H22: =SUMIFS(Gastos!D:D,Gastos!G:G,$B$3,Gastos!F:F,$B$2,Gastos!H:H,5,Gastos!B:B,"Otros") -> 0 | I22: =E22+F22+G22+H22 -> 0 | J22: =D22-I22 -> 0 | K22: =K21+J22 -> 0
... A46: Semana 40 | B46: =SUMIFS(Servicios!G:G,Servicios!L:L,$B$3,Servicios!K:K,$B$2,Servicios!M:M,5) -> 0 | D46: =B46+C46 -> 0 | E46: =SUMIFS(Gastos!D:D,Gastos!G:G,$B$3,Gastos!F:F,$B$2,Gastos!H:H,5,Gastos!B:B,"Insumos") -> 0 | F46: =SUMIFS(Gastos!D:D,Gastos!G:G,$B$3,Gastos!F:F,$B$2,Gastos!H:H,5,Gastos!B:B,"Combustible") -> 0 | G46: =SUMIFS(Gastos!D:D,Gastos!G:G,$B$3,Gastos!F:F,$B$2,Gastos!H:H,5,Gastos!B:B,"Sueldos") -> 0 | H46: =SUMIFS(Gastos!D:D,Gastos!G:G,$B$3,Gastos!F:F,$B$2,Gastos!H:H,5,Gastos!B:B,"Otros") -> 0 | I46: =E46+F46+G46+H46 -> 0 | J46: =D46-I46 -> 0 | K46: =K45+J46 -> 0

Sheet Mensual
A1: Parámetros | B1: Mes | C1: Ingresos por servicios | D1: Otros ingresos | E1: Total ingresos | F1: Costos variables (insumos) | G1: Combustible | H1: Sueldos | I1: Otros gastos fijos | J1: Total egresos | K1: Flujo neto | L1: Saldo acumulado
A2: Año | B2: 2025
A3: 2 | B3: Febrero
A4: Resumen Mensual (Año en B2) | B4: Marzo
A5: 4 | B5: Abril
A6: 5 | B6: Mayo | C6: =SUMIFS(Servicios!G:G,Servicios!L:L,$B$2,Servicios!K:K,A6) -> 0 | E6: =C6+D6 -> 0 | F6: =SUMIFS(Gastos!D:D,Gastos!G:G,$B$2,Gastos!F:F,A6,Gastos!B:B,"Insumos") -> 0 | G6: =SUMIFS(Gastos!D:D,Gastos!G:G,$B$2,Gastos!F:F,A6,Gastos!B:B,"Combustible") -> 0 | H6: =SUMIFS(Gastos!D:D,Gastos!G:G,$B$2,Gastos!F:F,A6,Gastos!B:B,"Sueldos") -> 0 | I6: =SUMIFS(Gastos!D:D,Gastos!G:G,$B$2,Gastos!F:F,A6,Gastos!B:B,"Otros") -> 0 | J6: =F6+G6+H6+I6 -> 0 | K6: =E6-J6 -> 0 | L6: =K6 -> 0
A7: 6 | B7: Junio | C7: =SUMIFS(Servicios!G:G,Servicios!L:L,$B$2,Servicios!K:K,A7) -> 0 | E7: =C7+D7 -> 0 | F7: =SUMIFS(Gastos!D:D,Gastos!G:G,$B$2,Gastos!F:F,A7,Gastos!B:B,"Insumos") -> 0 | G7: =SUMIFS(Gastos!D:D,Gastos!G:G,$B$2,Gastos!F:F,A7,Gastos!B:B,"Combustible") -> 0 | H7: =SUMIFS(Gastos!D:D,Gastos!G:G,$B$2,Gastos!F:F,A7,Gastos!B:B,"Sueldos") -> 0 | I7: =SUMIFS(Gastos!D:D,Gastos!G:G,$B$2,Gastos!F:F,A7,Gastos!B:B,"Otros") -> 0 | J7: =F7+G7+H7+I7 -> 0 | K7: =E7-J7 -> 0 | L7: =L6+K7 -> 0
A8: 7 | B8: Julio | C8: =SUMIFS(Servicios!H:H,Servicios!M:M,$B$2,Servicios!L:L,A8) -> 0 | E8: =C8+D8 -> 0 | F8: =SUMIFS(Gastos!D:D,Gastos!G:G,$B$2,Gastos!F:F,A8,Gastos!B:B,"Insumos") -> 0 | G8: =SUMIFS(Gastos!D:D,Gastos!G:G,$B$2,Gastos!F:F,A8,Gastos!B:B,"Combustible") -> 0 | H8: =SUMIFS(Gastos!D:D,Gastos!G:G,$B$2,Gastos!F:F,A8,Gastos!B:B,"Sueldos") -> 0 | I8: =SUMIFS(Gastos!D:D,Gastos!G:G,$B$2,Gastos!F:F,A8,Gastos!B:B,"Otros") -> 0 | J8: =F8+G8+H8+I8 -> 0 | K8: =E8-J8 -> 0 | L8: =L7+K8 -> 0
A9: 45870 | B9: 45870 | C9: =SUMIFS(Servicios!H:H,Servicios!O:O,A9) -> 65000 | E9: =C9+D9 -> 65000 | F9: =SUMIFS(Gastos!D:D,Gastos!G:G,$B$2,Gastos!F:F,A9,Gastos!B:B,"Insumos") -> 0 | G9: =SUMIFS(Gastos!D:D,Gastos!G:G,$B$2,Gastos!F:F,A9,Gastos!B:B,"Combustible") -> 0 | H9: =SUMIFS(Gastos!D:D,Gastos!G:G,$B$2,Gastos!F:F,A9,Gastos!B:B,"Sueldos") -> 0 | I9: =SUMIFS(Gastos!D:D,Gastos!G:G,$B$2,Gastos!F:F,A9,Gastos!B:B,"Otros") -> 0 | J9: =F9+G9+H9+I9 -> 0 | K9: =E9-J9 -> 65000 | L9: =L8+K9 -> 65000
A10: 45901 | B10: 45901 | C10: =SUMIFS(Servicios!H:H,Servicios!O:O,A10) -> 425540 | E10: =C10+D10 -> 425540 | F10: =SUMIFS(Gastos!D:D,Gastos!G:G,$B$2,Gastos!F:F,A10,Gastos!B:B,"Insumos") -> 0 | G10: =SUMIFS(Gastos!D:D,Gastos!G:G,$B$2,Gastos!F:F,A10,Gastos!B:B,"Combustible") -> 0 | H10: =SUMIFS(Gastos!D:D,Gastos!G:G,$B$2,Gastos!F:F,A10,Gastos!B:B,"Sueldos") -> 0 | I10: =SUMIFS(Gastos!D:D,Gastos!G:G,$B$2,Gastos!F:F,A10,Gastos!B:B,"Otros") -> 0 | J10: =F10+G10+H10+I10 -> 0 | K10: =E10-J10 -> 425540 | L10: =L9+K10 -> 490540
A11: 45931 | B11: 45931 | C11: =SUMIFS(Servicios!H:H,Servicios!O:O,A11) -> 1375100 | E11: =C11+D11 -> 1375100 | F11: =SUMIFS(Gastos!D:D,Gastos!G:G,$B$2,Gastos!F:F,A11,Gastos!B:B,"Insumos") -> 0 | G11: =SUMIFS(Gastos!D:D,Gastos!G:G,$B$2,Gastos!F:F,A11,Gastos!B:B,"Combustible") -> 0 | H11: =SUMIFS(Gastos!D:D,Gastos!G:G,$B$2,Gastos!F:F,A11,Gastos!B:B,"Sueldos") -> 0 | I11: =SUMIFS(Gastos!D:D,Gastos!G:G,$B$2,Gastos!F:F,A11,Gastos!B:B,"Otros") -> 0 | J11: =F11+G11+H11+I11 -> 0 | K11: =E11-J11 -> 1375100 | L11: =L10+K11 -> 1865640
A12: 45962 | B12: 45962 | C12: =SUMIFS(Servicios!H:H,Servicios!O:O,A12) -> 899000 | E12: =C12+D12 -> 899000 | F12: =SUMIFS(Gastos!D:D,Gastos!G:G,$B$2,Gastos!F:F,A12,Gastos!B:B,"Insumos") -> 0 | G12: =SUMIFS(Gastos!D:D,Gastos!G:G,$B$2,Gastos!F:F,A12,Gastos!B:B,"Combustible") -> 0 | H12: =SUMIFS(Gastos!D:D,Gastos!G:G,$B$2,Gastos!F:F,A12,Gastos!B:B,"Sueldos") -> 0 | I12: =SUMIFS(Gastos!D:D,Gastos!G:G,$B$2,Gastos!F:F,A12,Gastos!B:B,"Otros") -> 0 | J12: =F12+G12+H12+I12 -> 0 | K12: =E12-J12 -> 899000 | L12: =L11+K12 -> 2764640
A13: 45992 | B13: 45992 | C13: =SUMIFS(Servicios!H:H,Servicios!O:O,A13) -> 1162500 | E13: =C13+D13 -> 1162500 | F13: =SUMIFS(Gastos!D:D,Gastos!G:G,$B$2,Gastos!F:F,A13,Gastos!B:B,"Insumos") -> 0 | G13: =SUMIFS(Gastos!D:D,Gastos!G:G,$B$2,Gastos!F:F,A13,Gastos!B:B,"Combustible") -> 0 | H13: =SUMIFS(Gastos!D:D,Gastos!G:G,$B$2,Gastos!F:F,A13,Gastos!B:B,"Sueldos") -> 0 | I13: =SUMIFS(Gastos!D:D,Gastos!G:G,$B$2,Gastos!F:F,A13,Gastos!B:B,"Otros") -> 0 | J13: =F13+G13+H13+I13 -> 0 | K13: =E13-J13 -> 1162500 | L13: =L12+K13 -> 3927140
A14: 46023 | B14: 46023 | C14: =SUMIFS(Servicios!H:H,Servicios!O:O,A14) -> 870400 | E14: =C14+D14 -> 870400 | F14: =SUMIFS(Gastos!D:D,Gastos!G:G,$B$2,Gastos!F:F,A14,Gastos!B:B,"Insumos") -> 0 | G14: =SUMIFS(Gastos!D:D,Gastos!G:G,$B$2,Gastos!F:F,A14,Gastos!B:B,"Combustible") -> 0 | H14: =SUMIFS(Gastos!D:D,Gastos!G:G,$B$2,Gastos!F:F,A14,Gastos!B:B,"Sueldos") -> 0 | I14: =SUMIFS(Gastos!D:D,Gastos!G:G,$B$2,Gastos!F:F,A14,Gastos!B:B,"Otros") -> 0 | J14: =F14+G14+H14+I14 -> 0 | K14: =E14-J14 -> 870400 | L14: =L13+K14 -> 4797540
A15: 46054 | B15: 46054 | C15: =SUMIFS(Servicios!H:H,Servicios!O:O,A15) -> 1024600 | E15: =C15+D15 -> 1024600 | F15: =SUMIFS(Gastos!D:D,Gastos!G:G,$B$2,Gastos!F:F,A15,Gastos!B:B,"Insumos") -> 0 | G15: =SUMIFS(Gastos!D:D,Gastos!G:G,$B$2,Gastos!F:F,A15,Gastos!B:B,"Combustible") -> 0 | H15: =SUMIFS(Gastos!D:D,Gastos!G:G,$B$2,Gastos!F:F,A15,Gastos!B:B,"Sueldos") -> 0 | I15: =SUMIFS(Gastos!D:D,Gastos!G:G,$B$2,Gastos!F:F,A15,Gastos!B:B,"Otros") -> 0 | J15: =F15+G15+H15+I15 -> 0 | K15: =E15-J15 -> 1024600 | L15: =L14+K15 -> 5822140
A16: 46082 | B16: 46082 | C16: =SUMIFS(Servicios!H:H,Servicios!O:O,A16) -> 518000 | E16: =C16+D16 -> 518000 | F16: =SUMIFS(Gastos!D:D,Gastos!G:G,$B$2,Gastos!F:F,A16,Gastos!B:B,"Insumos") -> 0 | G16: =SUMIFS(Gastos!D:D,Gastos!G:G,$B$2,Gastos!F:F,A16,Gastos!B:B,"Combustible") -> 0 | H16: =SUMIFS(Gastos!D:D,Gastos!G:G,$B$2,Gastos!F:F,A16,Gastos!B:B,"Sueldos") -> 0 | I16: =SUMIFS(Gastos!D:D,Gastos!G:G,$B$2,Gastos!F:F,A16,Gastos!B:B,"Otros") -> 0 | J16: =F16+G16+H16+I16 -> 0 | K16: =E16-J16 -> 518000 | L16: =L15+K16 -> 6340140
A17: 46113 | B17: 46113 | C17: =SUMIFS(Servicios!H:H,Servicios!O:O,A17) -> 195000 | E17: =C17+D17 -> 195000 | F17: =SUMIFS(Gastos!D:D,Gastos!G:G,$B$2,Gastos!F:F,A17,Gastos!B:B,"Insumos") -> 0 | G17: =SUMIFS(Gastos!D:D,Gastos!G:G,$B$2,Gastos!F:F,A17,Gastos!B:B,"Combustible") -> 0 | H17: =SUMIFS(Gastos!D:D,Gastos!G:G,$B$2,Gastos!F:F,A17,Gastos!B:B,"Sueldos") -> 0 | I17: =SUMIFS(Gastos!D:D,Gastos!G:G,$B$2,Gastos!F:F,A17,Gastos!B:B,"Otros") -> 0 | J17: =F17+G17+H17+I17 -> 0 | K17: =E17-J17 -> 195000 | L17: =L16+K17 -> 6535140
E19: =SUM(E2:E17) -> 6535140

Sheet graficos
A1: Ticket promedio (CLP) | B1: =IFERROR(SUM(Servicios!H:H)/COUNT(Servicios!H:H),0) -> 45901.678
